Internal Server Error: /upload/
Traceback (most recent call last):
  File "D:\compare_data\env\Lib\site-packages\django\utils\datastructures.py", line 84, in __getitem__
    list_ = super().__getitem__(key)
            ^^^^^^^^^^^^^^^^^^^^^^^^
KeyError: 'file'

During handling of the above exception, another exception occurred:

Traceback (most recent call last):
  File "D:\compare_data\env\Lib\site-packages\django\core\handlers\exception.py", line 55, in inner
    response = get_response(request)
               ^^^^^^^^^^^^^^^^^^^^^
  File "D:\compare_data\env\Lib\site-packages\django\core\handlers\base.py", line 197, in _get_response
    response = wrapped_callback(request, *callback_args, **callback_kwargs)
               ^^^^^^^^^^^^^^^^^^^^^^^^^^^^^^^^^^^^^^^^^^^^^^^^^^^^^^^^^^^^
  File "D:\compare_data\scaling_mpr\upload\views.py", line 13, in upload_files
    uploaded_file = request.FILES['file']
                    ~~~~~~~~~~~~~^^^^^^^^
  File "D:\compare_data\env\Lib\site-packages\django\utils\datastructures.py", line 86, in __getitem__
    raise MultiValueDictKeyError(key)
django.utils.datastructures.MultiValueDictKeyError: 'file'
"POST /upload/ HTTP/1.1" 500 76981
